<?xml version="1.0"?>
<robot name="garcom_robot" xmlns:xacro="http://www.ros.org/wiki/xacro">

  <!-- ========================= -->
  <!-- Propriedades principais   -->
  <!-- ========================= -->

  <xacro:property name="base_length" value="0.45"/>
  <xacro:property name="base_width"  value="0.32"/>
  <xacro:property name="base_height" value="0.18"/>

  <xacro:property name="wheel_radius" value="0.075"/>
  <xacro:property name="wheel_width"  value="0.04"/>
  <xacro:property name="wheel_y"      value="0.18"/>

  <!-- ========================= -->
  <!-- Materiais                 -->
  <!-- ========================= -->

  <material name="blue">
    <color rgba="0.1 0.2 0.8 1.0"/>
  </material>

  <material name="black">
    <color rgba="0.02 0.02 0.02 1.0"/>
  </material>

  <material name="gray">
    <color rgba="0.5 0.5 0.5 1.0"/>
  </material>

  <!-- ========================= -->
  <!-- Base footprint            -->
  <!-- ========================= -->

  <link name="base_footprint"/>

  <joint name="base_footprint_joint" type="fixed">
    <parent link="base_footprint"/>
    <child link="base_link"/>
    <origin xyz="0 0 0.12" rpy="0 0 0"/>
  </joint>

  <!-- ========================= -->
  <!-- Corpo principal           -->
  <!-- ========================= -->

  <link name="base_link">
    <visual>
      <origin xyz="0 0 0" rpy="0 0 0"/>
      <geometry>
        <box size="${base_length} ${base_width} ${base_height}"/>
      </geometry>
      <material name="blue"/>
    </visual>

    <collision>
      <origin xyz="0 0 0" rpy="0 0 0"/>
      <geometry>
        <box size="${base_length} ${base_width} ${base_height}"/>
      </geometry>
    </collision>

    <inertial>
      <mass value="5.0"/>
      <origin xyz="0 0 0"/>
      <inertia ixx="0.08" ixy="0" ixz="0" iyy="0.10" iyz="0" izz="0.12"/>
    </inertial>
  </link>

  <!-- ========================= -->
  <!-- Roda esquerda             -->
  <!-- ========================= -->

  <link name="left_wheel_link">
    <visual>
      <origin xyz="0 0 0" rpy="1.5708 0 0"/>
      <geometry>
        <cylinder radius="${wheel_radius}" length="${wheel_width}"/>
      </geometry>
      <material name="black"/>
    </visual>

    <collision>
      <origin xyz="0 0 0" rpy="1.5708 0 0"/>
      <geometry>
        <cylinder radius="${wheel_radius}" length="${wheel_width}"/>
      </geometry>
    </collision>

    <inertial>
      <mass value="0.5"/>
      <origin xyz="0 0 0"/>
      <inertia ixx="0.001" ixy="0" ixz="0" iyy="0.001" iyz="0" izz="0.001"/>
    </inertial>
  </link>

  <joint name="left_wheel_joint" type="continuous">
    <parent link="base_link"/>
    <child link="left_wheel_link"/>
    <origin xyz="0 ${wheel_y} -0.045" rpy="0 0 0"/>
    <axis xyz="0 1 0"/>
  </joint>

  <!-- ========================= -->
  <!-- Roda direita              -->
  <!-- ========================= -->

  <link name="right_wheel_link">
    <visual>
      <origin xyz="0 0 0" rpy="1.5708 0 0"/>
      <geometry>
        <cylinder radius="${wheel_radius}" length="${wheel_width}"/>
      </geometry>
      <material name="black"/>
    </visual>

    <collision>
      <origin xyz="0 0 0" rpy="1.5708 0 0"/>
      <geometry>
        <cylinder radius="${wheel_radius}" length="${wheel_width}"/>
      </geometry>
    </collision>

    <inertial>
      <mass value="0.5"/>
      <origin xyz="0 0 0"/>
      <inertia ixx="0.001" ixy="0" ixz="0" iyy="0.001" iyz="0" izz="0.001"/>
    </inertial>
  </link>

  <joint name="right_wheel_joint" type="continuous">
    <parent link="base_link"/>
    <child link="right_wheel_link"/>
    <origin xyz="0 -${wheel_y} -0.045" rpy="0 0 0"/>
    <axis xyz="0 1 0"/>
  </joint>

  <!-- ========================= -->
  <!-- Roda caster traseira      -->
  <!-- ========================= -->

  <link name="caster_link">
    <visual>
      <origin xyz="0 0 0"/>
      <geometry>
        <sphere radius="0.03"/>
      </geometry>
      <material name="gray"/>
    </visual>

    <collision>
      <origin xyz="0 0 0"/>
      <geometry>
        <sphere radius="0.03"/>
      </geometry>
    </collision>

    <inertial>
      <mass value="0.2"/>
      <origin xyz="0 0 0"/>
      <inertia ixx="0.0002" ixy="0" ixz="0" iyy="0.0002" iyz="0" izz="0.0002"/>
    </inertial>
  </link>

  <joint name="caster_joint" type="fixed">
    <parent link="base_link"/>
    <child link="caster_link"/>
    <origin xyz="-0.18 0 -0.09" rpy="0 0 0"/>
  </joint>

  <!-- ========================= -->
  <!-- Sensor laser              -->
  <!-- ========================= -->

  <link name="laser_link">
    <visual>
      <origin xyz="0 0 0"/>
      <geometry>
        <cylinder radius="0.045" length="0.04"/>
      </geometry>
      <material name="gray"/>
    </visual>

    <collision>
      <origin xyz="0 0 0"/>
      <geometry>
        <cylinder radius="0.045" length="0.04"/>
      </geometry>
    </collision>

    <inertial>
      <mass value="0.1"/>
      <origin xyz="0 0 0"/>
      <inertia ixx="0.0001" ixy="0" ixz="0" iyy="0.0001" iyz="0" izz="0.0001"/>
    </inertial>
  </link>

  <joint name="laser_joint" type="fixed">
    <parent link="base_link"/>
    <child link="laser_link"/>
    <origin xyz="0.16 0 0.13" rpy="0 0 0"/>
  </joint>

  <!-- ========================= -->
  <!-- Gazebo: cores             -->
  <!-- ========================= -->

  <gazebo reference="base_link">
    <material>Gazebo/Blue</material>
  </gazebo>

  <gazebo reference="left_wheel_link">
    <material>Gazebo/Black</material>
    <mu1>1.0</mu1>
    <mu2>1.0</mu2>
  </gazebo>

  <gazebo reference="right_wheel_link">
    <material>Gazebo/Black</material>
    <mu1>1.0</mu1>
    <mu2>1.0</mu2>
  </gazebo>

  <gazebo reference="caster_link">
    <material>Gazebo/Grey</material>
    <mu1>0.1</mu1>
    <mu2>0.1</mu2>
  </gazebo>

  <!-- ========================= -->
  <!-- Plugin diferencial        -->
  <!-- ========================= -->

  <gazebo>
    <plugin name="differential_drive_controller" filename="libgazebo_ros_diff_drive.so">
      <robotNamespace>/</robotNamespace>

      <leftJoint>left_wheel_joint</leftJoint>
      <rightJoint>right_wheel_joint</rightJoint>

      <wheelSeparation>0.36</wheelSeparation>
      <wheelDiameter>0.15</wheelDiameter>

      <commandTopic>cmd_vel</commandTopic>
      <odometryTopic>odom</odometryTopic>
      <odometryFrame>odom</odometryFrame>
      <robotBaseFrame>base_footprint</robotBaseFrame>

      <publishWheelTF>false</publishWheelTF>
      <publishWheelJointState>true</publishWheelJointState>
      <publishTf>true</publishTf>

      <updateRate>50</updateRate>
    </plugin>
  </gazebo>

  <!-- ========================= -->
  <!-- Plugin do laser           -->
  <!-- ========================= -->

  <gazebo reference="laser_link">
    <sensor type="ray" name="laser_sensor">
      <pose>0 0 0 0 0 0</pose>
      <visualize>true</visualize>
      <update_rate>10</update_rate>

      <ray>
        <scan>
          <horizontal>
            <samples>360</samples>
            <resolution>1</resolution>
            <min_angle>-3.14159</min_angle>
            <max_angle>3.14159</max_angle>
          </horizontal>
        </scan>

        <range>
          <min>0.12</min>
          <max>8.0</max>
          <resolution>0.01</resolution>
        </range>
      </ray>

      <plugin name="gazebo_ros_laser_controller" filename="libgazebo_ros_laser.so">
        <topicName>scan</topicName>
        <frameName>laser_link</frameName>
      </plugin>
    </sensor>
  </gazebo>

</robot>
